Workbook

Sheet Order
P1: QTY L2 | Q1: QTY L3 Opt.
A2: Serial | B2: STL PN | C2: Supplier | D2: ADIENT PN | E2: DESCRIPTION | F2: unit | G2: L2 | H2: Driver | I2: Passenger | J2: Rearseat | K2: L3 Opt. | L2: Driver | M2: Passenger | N2: Rearseat | O2: MOQ | P2: =(31*48) -> 1488 | Q2: =(47*48) -> 2256 | R2: Diff with stock | S2: Diff with stock in MOQ | T2: MOQ Order L2 | U2: MOQ Order L3 OPT | V2: QTY after MOQ L2 | W2: QTY after MOQ L3 Opt | X2: Final order L2 | Y2: Final order L3 Opt. | Z2: non accumulative order | AA2: accumulative order
A3: 1 | B3: 9823868480 | C3: Adient Zaragoza | D3: 4207718-0-9 | E3: MANUAL - FRONT RIGHT SEAT BACKREST FRAME | F3: EA | G3: 1 | H3: 0 | I3: 1 | J3: 0 | K3: 1 | L3: 0 | M3: 1 | N3: 0 | O3: 20 | P3: =G3*$P$2 -> 1488 | Q3: =K3*$Q$2 -> 2256 | R3: =(P3+Q3)-Stock!E3 -> 898 | S3: =ROUNDUP(R3/O3,0) -> 45 | T3: =ROUNDUP($P$2/O3*G3,0) -> 75 | U3: =ROUNDUP($Q$2/O3*K3,0) -> 113 | V3: =T3*O3 -> 1500 | W3: =O3*U3 -> 2260 | X3: {=_xlfn.IFS(P3+Q3>Stock!E3,V3,P3+Q3<Stock!E3,"No need",Stock!E3=0,V3,P3+Q3=Stock!E3,"No need")} -> 1500 | Y3: {=_xlfn.IFS(P3+Q3>Stock!E3,W3,P3+Q3<Stock!E3,"No need",Stock!E3=0,W3,P3+Q3=Stock!E3,"No need")} -> 2260 | Z3: {=_xlfn.IFS(ISNUMBER(X3+Y3),X3+Y3,ISTEXT(X3&Y3),"No need")} -> 3760 | AA3: {=_xlfn.IFS(S3*O3>0,S3*O3,S3*O3<0,"No need",S3*O3=0,0)} -> 900
A4: 2 | B4: 9823868180 | C4: Adient Zaragoza | D4: 4812333-0-9 | E4: POWER - FRONT SEAT LEFT / RIGHT BACKREST FRAME - NON MEMO | F4: EA | G4: 0 | H4: 0 | I4: 0 | J4: 0 | K4: 1 | L4: 1 | M4: 0 | N4: 0 | O4: 20 | P4: =G4*$P$2 -> 0 | Q4: =K4*$Q$2 -> 2256 | R4: =(P4+Q4)-Stock!E4 -> 567 | S4: =ROUNDUP(R4/O4,0) -> 29 | T4: =ROUNDUP($P$2/O4*G4,0) -> 0 | U4: =ROUNDUP($Q$2/O4*K4,0) -> 113 | V4: =T4*O4 -> 0 | W4: =O4*U4 -> 2260 | X4: {=_xlfn.IFS(P4+Q4>Stock!E4,V4,P4+Q4<Stock!E4,"No need",Stock!E4=0,V4,P4+Q4=Stock!E4,"No need")} -> 0 | Y4: {=_xlfn.IFS(P4+Q4>Stock!E4,W4,P4+Q4<Stock!E4,"No need",Stock!E4=0,W4,P4+Q4=Stock!E4,"No need")} -> 2260 | Z4: {=_xlfn.IFS(ISNUMBER(X4+Y4),X4+Y4,ISTEXT(X4&Y4),"No need")} -> 2260 | AA4: {=_xlfn.IFS(S4*O4>0,S4*O4,S4*O4<0,"No need",S4*O4=0,0)} -> 580
A5: 3 | B5: 9823868280 | C5: Adient Zaragoza | D5: 4207618-0-9 | E5: MANUAL - FRONT LEFT SEAT BACKREST FRAME | F5: EA | G5: 1 | H5: 1 | I5: 0 | J5: 0 | K5: 0 | L5: 0 | M5: 0 | N5: 0 | O5: 20 | P5: =G5*$P$2 -> 1488 | Q5: =K5*$Q$2 -> 0 | R5: =(P5+Q5)-Stock!E5 -> 323 | S5: =ROUNDUP(R5/O5,0) -> 17 | T5: =ROUNDUP($P$2/O5*G5,0) -> 75 | U5: =ROUNDUP($Q$2/O5*K5,0) -> 0 | V5: =T5*O5 -> 1500 | W5: =O5*U5 -> 0 | X5: {=_xlfn.IFS(P5+Q5>Stock!E5,V5,P5+Q5<Stock!E5,"No need",Stock!E5=0,V5,P5+Q5=Stock!E5,"No need")} -> 1500 | Y5: {=_xlfn.IFS(P5+Q5>Stock!E5,W5,P5+Q5<Stock!E5,"No need",Stock!E5=0,W5,P5+Q5=Stock!E5,"No need")} -> 0 | Z5: {=_xlfn.IFS(ISNUMBER(X5+Y5),X5+Y5,ISTEXT(X5&Y5),"No need")} -> 1500 | AA5: {=_xlfn.IFS(S5*O5>0,S5*O5,S5*O5<0,"No need",S5*O5=0,0)} -> 340
A6: 4 | B6: 9832027580 | C6: Adient Zaragoza | D6: 4355899-0-9 | E6: 6WAY MANUAL - FRONT LHD PASSANGER SEAT CUSHION FRAME 6WAY MANUAL - FRONT RHD DRIVER SEAT CUSHION FRAME | F6: EA | G6: 1 | H6: 0 | I6: 1 | J6: 0 | K6: 1 | L6: 0 | M6: 1 | N6: 0 | O6: 12 | P6: =G6*$P$2 -> 1488 | Q6: =K6*$Q$2 -> 2256 | R6: =(P6+Q6)-Stock!E6 -> 906 | S6: =ROUNDUP(R6/O6,0) -> 76 | T6: =ROUNDUP($P$2/O6*G6,0) -> 124 | U6: =ROUNDUP($Q$2/O6*K6,0) -> 188 | V6: =T6*O6 -> 1488 | W6: =O6*U6 -> 2256 | X6: {=_xlfn.IFS(P6+Q6>Stock!E6,V6,P6+Q6<Stock!E6,"No need",Stock!E6=0,V6,P6+Q6=Stock!E6,"No need")} -> 1488 | Y6: {=_xlfn.IFS(P6+Q6>Stock!E6,W6,P6+Q6<Stock!E6,"No need",Stock!E6=0,W6,P6+Q6=Stock!E6,"No need")} -> 2256 | Z6: {=_xlfn.IFS(ISNUMBER(X6+Y6),X6+Y6,ISTEXT(X6&Y6),"No need")} -> 3744 | AA6: {=_xlfn.IFS(S6*O6>0,S6*O6,S6*O6<0,"No need",S6*O6=0,0)} -> 912
A7: 5 | B7: 9832021380 | C7: Adient Zaragoza | D7: 4812346-0-9 | E7: 6WAY HYBRID - FRONT LHD DRIVER SEAT CUSHION FRAME | F7: EA | G7: 0 | H7: 0 | I7: 0 | J7: 0 | K7: 1 | L7: 1 | M7: 0 | N7: 0 | O7: 12 | P7: =G7*$P$2 -> 0 | Q7: =K7*$Q$2 -> 2256 | R7: =(P7+Q7)-Stock!E7 -> 564 | S7: =ROUNDUP(R7/O7,0) -> 47 | T7: =ROUNDUP($P$2/O7*G7,0) -> 0 | U7: =ROUNDUP($Q$2/O7*K7,0) -> 188 | V7: =T7*O7 -> 0 | W7: =O7*U7 -> 2256 | X7: {=_xlfn.IFS(P7+Q7>Stock!E7,V7,P7+Q7<Stock!E7,"No need",Stock!E7=0,V7,P7+Q7=Stock!E7,"No need")} -> 0 | Y7: {=_xlfn.IFS(P7+Q7>Stock!E7,W7,P7+Q7<Stock!E7,"No need",Stock!E7=0,W7,P7+Q7=Stock!E7,"No need")} -> 2256 | Z7: {=_xlfn.IFS(ISNUMBER(X7+Y7),X7+Y7,ISTEXT(X7&Y7),"No need")} -> 2256 | AA7: {=_xlfn.IFS(S7*O7>0,S7*O7,S7*O7<0,"No need",S7*O7=0,0)} -> 564
A8: 6 | B8: 9832021180 | C8: Adient Zaragoza | D8: 4207871-0-9 | E8: 6WAY MANUAL - FRONT LHD DRIVER SEAT CUSHION FRAME 6WAY MANUAL - FRONT RHD PASSENGER SEAT CUSHION FRAME | F8: EA | G8: 1 | H8: 1 | I8: 0 | J8: 0 | K8: 0 | L8: 0 | M8: 0 | N8: 0 | O8: 12 | P8: =G8*$P$2 -> 1488 | Q8: =K8*$Q$2 -> 0 | R8: =(P8+Q8)-Stock!E8 -> 327 | S8: =ROUNDUP(R8/O8,0) -> 28 | T8: =ROUNDUP($P$2/O8*G8,0) -> 124 | U8: =ROUNDUP($Q$2/O8*K8,0) -> 0 | V8: =T8*O8 -> 1488 | W8: =O8*U8 -> 0 | X8: {=_xlfn.IFS(P8+Q8>Stock!E8,V8,P8+Q8<Stock!E8,"No need",Stock!E8=0,V8,P8+Q8=Stock!E8,"No need")} -> 1488 | Y8: {=_xlfn.IFS(P8+Q8>Stock!E8,W8,P8+Q8<Stock!E8,"No need",Stock!E8=0,W8,P8+Q8=Stock!E8,"No need")} -> 0 | Z8: {=_xlfn.IFS(ISNUMBER(X8+Y8),X8+Y8,ISTEXT(X8&Y8),"No need")} -> 1488 | AA8: {=_xlfn.IFS(S8*O8>0,S8*O8,S8*O8<0,"No need",S8*O8=0,0)} -> 336
A9: 7 | B9: 9833400580 | C9: Adient Zaragoza | D9: 4171294-0-8 | E9: REAR SEAT BACKREST FRAME 40% | F9: EA | G9: 1 | H9: 0 | I9: 0 | J9: 1 | K9: 1 | L9: 0 | M9: 0 | N9: 1 | O9: 36 | P9: =G9*$P$2 -> 1488 | Q9: =K9*$Q$2 -> 2256 | R9: =(P9+Q9)-Stock!E9 -> 895 | S9: =ROUNDUP(R9/O9,0) -> 25 | T9: =ROUNDUP($P$2/O9*G9,0) -> 42 | U9: =ROUNDUP($Q$2/O9*K9,0) -> 63 | V9: =T9*O9 -> 1512 | W9: =O9*U9 -> 2268 | X9: {=_xlfn.IFS(P9+Q9>Stock!E9,V9,P9+Q9<Stock!E9,"No need",Stock!E9=0,V9,P9+Q9=Stock!E9,"No need")} -> 1512 | Y9: {=_xlfn.IFS(P9+Q9>Stock!E9,W9,P9+Q9<Stock!E9,"No need",Stock!E9=0,W9,P9+Q9=Stock!E9,"No need")} -> 2268 | Z9: {=_xlfn.IFS(ISNUMBER(X9+Y9),X9+Y9,ISTEXT(X9&Y9),"No need")} -> 3780 | AA9: {=_xlfn.IFS(S9*O9>0,S9*O9,S9*O9<0,"No need",S9*O9=0,0)} -> 900
A10: 8 | B10: 9833208180 | C10: Adient Zaragoza | D10: 4171342-0-8 | E10: REAR SEAT BACKREST FRAME 60% W/ ARMREST | F10: EA | G10: 0 | H10: 0 | I10: 0 | J10: 0 | K10: 1 | L10: 0 | M10: 0 | N10: 1 | O10: 18 | P10: =G10*$P$2 -> 0 | Q10: =K10*$Q$2 -> 2256 | R10: =(P10+Q10)-Stock!E10 -> 564 | S10: =ROUNDUP(R10/O10,0) -> 32 | T10: =ROUNDUP($P$2/O10*G10,0) -> 0 | U10: =ROUNDUP($Q$2/O10*K10,0) -> 126 | V10: =T10*O10 -> 0 | W10: =O10*U10 -> 2268 | X10: {=_xlfn.IFS(P10+Q10>Stock!E10,V10,P10+Q10<Stock!E10,"No need",Stock!E10=0,V10,P10+Q10=Stock!E10,"No need")} -> 0 | Y10: {=_xlfn.IFS(P10+Q10>Stock!E10,W10,P10+Q10<Stock!E10,"No need",Stock!E10=0,W10,P10+Q10=Stock!E10,"No need")} -> 2268 | Z10: {=_xlfn.IFS(ISNUMBER(X10+Y10),X10+Y10,ISTEXT(X10&Y10),"No need")} -> 2268 | AA10: {=_xlfn.IFS(S10*O10>0,S10*O10,S10*O10<0,"No need",S10*O10=0,0)} -> 576
A11: 9 | B11: 9833208280 | C11: Adient Zaragoza | D11: 4171338-0-8 | E11: REAR SEAT BACKREST FRAME 60% W/O ARMREST | F11: EA | G11: 1 | H11: 0 | I11: 0 | J11: 1 | K11: 0 | L11: 0 | M11: 0 | N11: 0 | O11: 18 | P11: =G11*$P$2 -> 1488 | Q11: =K11*$Q$2 -> 0 | R11: =(P11+Q11)-Stock!E11 -> 331 | S11: =ROUNDUP(R11/O11,0) -> 19 | T11: =ROUNDUP($P$2/O11*G11,0) -> 83 | U11: =ROUNDUP($Q$2/O11*K11,0) -> 0 | V11: =T11*O11 -> 1494 | W11: =O11*U11 -> 0 | X11: {=_xlfn.IFS(P11+Q11>Stock!E11,V11,P11+Q11<Stock!E11,"No need",Stock!E11=0,V11,P11+Q11=Stock!E11,"No need")} -> 1494 | Y11: {=_xlfn.IFS(P11+Q11>Stock!E11,W11,P11+Q11<Stock!E11,"No need",Stock!E11=0,W11,P11+Q11=Stock!E11,"No need")} -> 0 | Z11: {=_xlfn.IFS(ISNUMBER(X11+Y11),X11+Y11,ISTEXT(X11&Y11),"No need")} -> 1494 | AA11: {=_xlfn.IFS(S11*O11>0,S11*O11,S11*O11<0,"No need",S11*O11=0,0)} -> 342
A12: 10 | B12: 9814491980 | C12: Adient Zaragoza | D12: 4171343-0-8 | E12: LATCH RH 40% | F12: EA | G12: 1 | H12: 0 | I12: 0 | J12: 1 | K12: 1 | L12: 0 | M12: 0 | N12: 1 | O12: 800 | P12: =G12*$P$2 -> 1488 | Q12: =K12*$Q$2 -> 2256 | R12: =(P12+Q12)-Stock!E12 -> 667 | S12: =ROUNDUP(R12/O12,0) -> 1 | T12: =ROUNDUP($P$2/O12*G12,0) -> 2 | U12: =ROUNDUP($Q$2/O12*K12,0) -> 3 | V12: =T12*O12 -> 1600 | W12: =O12*U12 -> 2400 | X12: {=_xlfn.IFS(P12+Q12>Stock!E12,V12,P12+Q12<Stock!E12,"No need",Stock!E12=0,V12,P12+Q12=Stock!E12,"No need")} -> 1600 | Y12: {=_xlfn.IFS(P12+Q12>Stock!E12,W12,P12+Q12<Stock!E12,"No need",Stock!E12=0,W12,P12+Q12=Stock!E12,"No need")} -> 2400 | Z12: {=_xlfn.IFS(ISNUMBER(X12+Y12),X12+Y12,ISTEXT(X12&Y12),"No need")} -> 4000 | AA12: {=_xlfn.IFS(S12*O12>0,S12*O12,S12*O12<0,"No need",S12*O12=0,0)} -> 800
A13: 11 | B13: 9814492580 | C13: Adient Zaragoza | D13: 4171348-0-8 | E13: LATCH LH 60% | F13: EA | G13: 1 | H13: 0 | I13: 0 | J13: 1 | K13: 1 | L13: 0 | M13: 0 | N13: 1 | O13: 800 | P13: =G13*$P$2 -> 1488 | Q13: =K13*$Q$2 -> 2256 | R13: =(P13+Q13)-Stock!E13 -> 673 | S13: =ROUNDUP(R13/O13,0) -> 1 | T13: =ROUNDUP($P$2/O13*G13,0) -> 2 | U13: =ROUNDUP($Q$2/O13*K13,0) -> 3 | V13: =T13*O13 -> 1600 | W13: =O13*U13 -> 2400 | X13: {=_xlfn.IFS(P13+Q13>Stock!E13,V13,P13+Q13<Stock!E13,"No need",Stock!E13=0,V13,P13+Q13=Stock!E13,"No need")} -> 1600 | Y13: {=_xlfn.IFS(P13+Q13>Stock!E13,W13,P13+Q13<Stock!E13,"No need",Stock!E13=0,W13,P13+Q13=Stock!E13,"No need")} -> 2400 | Z13: {=_xlfn.IFS(ISNUMBER(X13+Y13),X13+Y13,ISTEXT(X13&Y13),"No need")} -> 4000 | AA13: {=_xlfn.IFS(S13*O13>0,S13*O13,S13*O13<0,"No need",S13*O13=0,0)} -> 800
A14: 12 | B14: 9818614480 | C14: Adient Zaragoza | D14: 4171684-0-9 | E14: GUIDE APPUI-TETE SIEGE AV G (LISSE) FRONT - NON LOCKING BEZEL | F14: EA | G14: 0 | H14: 0 | I14: 0 | J14: 0 | K14: 5 | L14: 1 | M14: 1 | N14: 3 | O14: 1000 | P14: =G14*$P$2 -> 0 | Q14: =K14*$Q$2 -> 11280 | R14: =(P14+Q14)-Stock!E14 -> 2880 | S14: =ROUNDUP(R14/O14,0) -> 3 | T14: =ROUNDUP($P$2/O14*G14,0) -> 0 | U14: =ROUNDUP($Q$2/O14*K14,0) -> 12 | V14: =T14*O14 -> 0 | W14: =O14*U14 -> 12000 | X14: {=_xlfn.IFS(P14+Q14>Stock!E14,V14,P14+Q14<Stock!E14,"No need",Stock!E14=0,V14,P14+Q14=Stock!E14,"No need")} -> 0 | Y14: {=_xlfn.IFS(P14+Q14>Stock!E14,W14,P14+Q14<Stock!E14,"No need",Stock!E14=0,W14,P14+Q14=Stock!E14,"No need")} -> 12000 | Z14: {=_xlfn.IFS(ISNUMBER(X14+Y14),X14+Y14,ISTEXT(X14&Y14),"No need")} -> 12000 | AA14: {=_xlfn.IFS(S14*O14>0,S14*O14,S14*O14<0,"No need",S14*O14=0,0)} -> 3000
A15: 13 | B15: 9818614580 | C15: Adient Zaragoza | D15: 4171687-0-9 | E15: FRONT - LOCKING BEZEL | F15: EA | G15: 0 | H15: 0 | I15: 0 | J15: 0 | K15: 5 | L15: 1 | M15: 1 | N15: 3 | O15: 1000 | P15: =G15*$P$2 -> 0 | Q15: =K15*$Q$2 -> 11280 | R15: =(P15+Q15)-Stock!E15 -> 2870 | S15: =ROUNDUP(R15/O15,0) -> 3 | T15: =ROUNDUP($P$2/O15*G15,0) -> 0 | U15: =ROUNDUP($Q$2/O15*K15,0) -> 12 | V15: =T15*O15 -> 0 | W15: =O15*U15 -> 12000 | X15: {=_xlfn.IFS(P15+Q15>Stock!E15,V15,P15+Q15<Stock!E15,"No need",Stock!E15=0,V15,P15+Q15=Stock!E15,"No need")} -> 0 | Y15: {=_xlfn.IFS(P15+Q15>Stock!E15,W15,P15+Q15<Stock!E15,"No need",Stock!E15=0,W15,P15+Q15=Stock!E15,"No need")} -> 12000 | Z15: {=_xlfn.IFS(ISNUMBER(X15+Y15),X15+Y15,ISTEXT(X15&Y15),"No need")} -> 12000 | AA15: {=_xlfn.IFS(S15*O15>0,S15*O15,S15*O15<0,"No need",S15*O15=0,0)} -> 3000
A16: 14 | B16: 9811628680 | C16: Adient Zaragoza | D16: 4171695-0-9 | E16: TRACK END CAP | F16: EA | G16: 0 | H16: 0 | I16: 0 | J16: 0 | K16: 6 | L16: 3 | M16: 3 | N16: 0 | O16: 3200 | P16: =G16*$P$2 -> 0 | Q16: =K16*$Q$2 -> 13536 | R16: =(P16+Q16)-Stock!E16 -> 1736 | S16: =ROUNDUP(R16/O16,0) -> 1 | T16: =ROUNDUP($P$2/O16*G16,0) -> 0 | U16: =ROUNDUP($Q$2/O16*K16,0) -> 5 | V16: =T16*O16 -> 0 | W16: =O16*U16 -> 16000 | X16: {=_xlfn.IFS(P16+Q16>Stock!E16,V16,P16+Q16<Stock!E16,"No need",Stock!E16=0,V16,P16+Q16=Stock!E16,"No need")} -> 0 | Y16: {=_xlfn.IFS(P16+Q16>Stock!E16,W16,P16+Q16<Stock!E16,"No need",Stock!E16=0,W16,P16+Q16=Stock!E16,"No need")} -> 16000 | Z16: {=_xlfn.IFS(ISNUMBER(X16+Y16),X16+Y16,ISTEXT(X16&Y16),"No need")} -> 16000 | AA16: {=_xlfn.IFS(S16*O16>0,S16*O16,S16*O16<0,"No need",S16*O16=0,0)} -> 3200
A17: 15 | B17: 9824492180 | C17: Adient Zaragoza | D17: 4171702-0-9 | E17: LH - SIDE COVER - 6WAY MANUAL | F17: EA | G17: 1 | H17: 1 | I17: 0 | J17: 0 | K17: 0 | L17: 0 | M17: 0 | N17: 0 | O17: 360 | P17: =G17*$P$2 -> 1488 | Q17: =K17*$Q$2 -> 0 | R17: =(P17+Q17)-Stock!E17 -> 65 | S17: =ROUNDUP(R17/O17,0) -> 1 | T17: =ROUNDUP($P$2/O17*G17,0) -> 5 | U17: =ROUNDUP($Q$2/O17*K17,0) -> 0 | V17: =T17*O17 -> 1800 | W17: =O17*U17 -> 0 | X17: {=_xlfn.IFS(P17+Q17>Stock!E17,V17,P17+Q17<Stock!E17,"No need",Stock!E17=0,V17,P17+Q17=Stock!E17,"No need")} -> 1800 | Y17: {=_xlfn.IFS(P17+Q17>Stock!E17,W17,P17+Q17<Stock!E17,"No need",Stock!E17=0,W17,P17+Q17=Stock!E17,"No need")} -> 0 | Z17: {=_xlfn.IFS(ISNUMBER(X17+Y17),X17+Y17,ISTEXT(X17&Y17),"No need")} -> 1800 | AA17: {=_xlfn.IFS(S17*O17>0,S17*O17,S17*O17<0,"No need",S17*O17=0,0)} -> 360
A18: 16 | B18: 9824487880 | C18: Adient Zaragoza | D18: 4171705-0-9 | E18: RH - SIDE COVER - 6WAY MANUAL | F18: EA | G18: 1 | H18: 0 | I18: 1 | J18: 0 | K18: 0 | L18: 0 | M18: 0 | N18: 0 | O18: 360 | P18: =G18*$P$2 -> 1488 | Q18: =K18*$Q$2 -> 0 | R18: =(P18+Q18)-Stock!E18 -> 63 | S18: =ROUNDUP(R18/O18,0) -> 1 | T18: =ROUNDUP($P$2/O18*G18,0) -> 5 | U18: =ROUNDUP($Q$2/O18*K18,0) -> 0 | V18: =T18*O18 -> 1800 | W18: =O18*U18 -> 0 | X18: {=_xlfn.IFS(P18+Q18>Stock!E18,V18,P18+Q18<Stock!E18,"No need",Stock!E18=0,V18,P18+Q18=Stock!E18,"No need")} -> 1800 | Y18: {=_xlfn.IFS(P18+Q18>Stock!E18,W18,P18+Q18<Stock!E18,"No need",Stock!E18=0,W18,P18+Q18=Stock!E18,"No need")} -> 0 | Z18: {=_xlfn.IFS(ISNUMBER(X18+Y18),X18+Y18,ISTEXT(X18&Y18),"No need")} -> 1800 | AA18: {=_xlfn.IFS(S18*O18>0,S18*O18,S18*O18<0,"No need",S18*O18=0,0)} -> 360
A19: 17 | B19: 9824523980 | C19: Adient Zaragoza | D19: 4171756-0-9 | E19: RECLINER INNER COVER - LH | F19: EA | G19: 1 | H19: 1 | I19: 0 | J19: 0 | K19: 1 | L19: 1 | M19: 0 | N19: 0 | O19: 440 | P19: =G19*$P$2 -> 1488 | Q19: =K19*$Q$2 -> 2256 | R19: =(P19+Q19)-Stock!E19 -> 794 | S19: =ROUNDUP(R19/O19,0) -> 2 | T19: =ROUNDUP($P$2/O19*G19,0) -> 4 | U19: =ROUNDUP($Q$2/O19*K19,0) -> 6 | V19: =T19*O19 -> 1760 | W19: =O19*U19 -> 2640 | X19: {=_xlfn.IFS(P19+Q19>Stock!E19,V19,P19+Q19<Stock!E19,"No need",Stock!E19=0,V19,P19+Q19=Stock!E19,"No need")} -> 1760 | Y19: {=_xlfn.IFS(P19+Q19>Stock!E19,W19,P19+Q19<Stock!E19,"No need",Stock!E19=0,W19,P19+Q19=Stock!E19,"No need")} -> 2640 | Z19: {=_xlfn.IFS(ISNUMBER(X19+Y19),X19+Y19,ISTEXT(X19&Y19),"No need")} -> 4400 | AA19: {=_xlfn.IFS(S19*O19>0,S19*O19,S19*O19<0,"No need",S19*O19=0,0)} -> 880
A20: 18 | B20: 9824522580 | C20: Adient Zaragoza | D20: 4171759-0-9 | E20: RECLINER INNER COVER - RH | F20: EA | G20: 1 | H20: 0 | I20: 1 | J20: 0 | K20: 1 | L20: 0 | M20: 1 | N20: 0 | O20: 440 | P20: =G20*$P$2 -> 1488 | Q20: =K20*$Q$2 -> 2256 | R20: =(P20+Q20)-Stock!E20 -> 796 | S20: =ROUNDUP(R20/O20,0) -> 2 | T20: =ROUNDUP($P$2/O20*G20,0) -> 4 | U20: =ROUNDUP($Q$2/O20*K20,0) -> 6 | V20: =T20*O20 -> 1760 | W20: =O20*U20 -> 2640 | X20: {=_xlfn.IFS(P20+Q20>Stock!E20,V20,P20+Q20<Stock!E20,"No need",Stock!E20=0,V20,P20+Q20=Stock!E20,"No need")} -> 1760 | Y20: {=_xlfn.IFS(P20+Q20>Stock!E20,W20,P20+Q20<Stock!E20,"No need",Stock!E20=0,W20,P20+Q20=Stock!E20,"No need")} -> 2640 | Z20: {=_xlfn.IFS(ISNUMBER(X20+Y20),X20+Y20,ISTEXT(X20&Y20),"No need")} -> 4400 | AA20: {=_xlfn.IFS(S20*O20>0,S20*O20,S20*O20<0,"No need",S20*O20=0,0)} -> 880
A21: 19 | B21: 9825038780 | C21: Adient Zaragoza | D21: 4171763-0-9 | E21: RECLINER HANDWHEEL - HARD | F21: EA | G21: 2 | H21: 1 | I21: 1 | J21: 0 | K21: 0 | L21: 0 | M21: 0 | N21: 0 | O21: 840 | P21: =G21*$P$2 -> 2976 | Q21: =K21*$Q$2 -> 0 | R21: =(P21+Q21)-Stock!E21 -> 571 | S21: =ROUNDUP(R21/O21,0) -> 1 | T21: =ROUNDUP($P$2/O21*G21,0) -> 4 | U21: =ROUNDUP($Q$2/O21*K21,0) -> 0 | V21: =T21*O21 -> 3360 | W21: =O21*U21 -> 0 | X21: {=_xlfn.IFS(P21+Q21>Stock!E21,V21,P21+Q21<Stock!E21,"No need",Stock!E21=0,V21,P21+Q21=Stock!E21,"No need")} -> 3360 | Y21: {=_xlfn.IFS(P21+Q21>Stock!E21,W21,P21+Q21<Stock!E21,"No need",Stock!E21=0,W21,P21+Q21=Stock!E21,"No need")} -> 0 | Z21: {=_xlfn.IFS(ISNUMBER(X21+Y21),X21+Y21,ISTEXT(X21&Y21),"No need")} -> 3360 | AA21: {=_xlfn.IFS(S21*O21>0,S21*O21,S21*O21<0,"No need",S21*O21=0,0)} -> 840
A22: 20 | B22: 9825048280 | C22: Adient Zaragoza | D22: 5222357-0-9 | E22: RECLINER HANDWHEEL - SOFT | F22: EA | G22: 0 | H22: 0 | I22: 0 | J22: 0 | K22: 1 | L22: 0 | M22: 1 | N22: 0 | O22: 1800 | P22: =G22*$P$2 -> 0 | Q22: =K22*$Q$2 -> 2256 | R22: =(P22+Q22)-Stock!E22 -> 511 | S22: =ROUNDUP(R22/O22,0) -> 1 | T22: =ROUNDUP($P$2/O22*G22,0) -> 0 | U22: =ROUNDUP($Q$2/O22*K22,0) -> 2 | V22: =T22*O22 -> 0 | W22: =O22*U22 -> 3600 | X22: {=_xlfn.IFS(P22+Q22>Stock!E22,V22,P22+Q22<Stock!E22,"No need",Stock!E22=0,V22,P22+Q22=Stock!E22,"No need")} -> 0 | Y22: {=_xlfn.IFS(P22+Q22>Stock!E22,W22,P22+Q22<Stock!E22,"No need",Stock!E22=0,W22,P22+Q22=Stock!E22,"No need")} -> 3600 | Z22: {=_xlfn.IFS(ISNUMBER(X22+Y22),X22+Y22,ISTEXT(X22&Y22),"No need")} -> 3600 | AA22: {=_xlfn.IFS(S22*O22>0,S22*O22,S22*O22<0,"No need",S22*O22=0,0)} -> 1800
A23: 21 | B23: 9825013880 | C23: Adient Zaragoza | D23: 4171767-0-9 | E23: RECLINER HANDWHEEL CAP | F23: EA | G23: 0 | H23: 0 | I23: 0 | J23: 0 | K23: 1 | L23: 0 | M23: 1 | N23: 0 | O23: 954 | P23: =G23*$P$2 -> 0 | Q23: =K23*$Q$2 -> 2256 | R23: =(P23+Q23)-Stock!E23 -> 552 | S23: =ROUNDUP(R23/O23,0) -> 1 | T23: =ROUNDUP($P$2/O23*G23,0) -> 0 | U23: =ROUNDUP($Q$2/O23*K23,0) -> 3 | V23: =T23*O23 -> 0 | W23: =O23*U23 -> 2862 | X23: {=_xlfn.IFS(P23+Q23>Stock!E23,V23,P23+Q23<Stock!E23,"No need",Stock!E23=0,V23,P23+Q23=Stock!E23,"No need")} -> 0 | Y23: {=_xlfn.IFS(P23+Q23>Stock!E23,W23,P23+Q23<Stock!E23,"No need",Stock!E23=0,W23,P23+Q23=Stock!E23,"No need")} -> 2862 | Z23: {=_xlfn.IFS(ISNUMBER(X23+Y23),X23+Y23,ISTEXT(X23&Y23),"No need")} -> 2862 | AA23: {=_xlfn.IFS(S23*O23>0,S23*O23,S23*O23<0,"No need",S23*O23=0,0)} -> 954
A24: 22 | B24: 9846498080 | C24: Adient Zaragoza | D24: 6201578-0-9 | E24: MECHANICAL LUMBAR HANDWHEEL LH & RH CDPO OPTIMIZED RADIUS | F24: EA | G24: 1 | H24: 1 | I24: 0 | J24: 0 | K24: 0 | L24: 0 | M24: 0 | N24: 0 | O24: 720 | P24: =G24*$P$2 -> 1488 | Q24: =K24*$Q$2 -> 0 | R24: =(P24+Q24)-Stock!E24 -> 98 | S24: =ROUNDUP(R24/O24,0) -> 1 | T24: =ROUNDUP($P$2/O24*G24,0) -> 3 | U24: =ROUNDUP($Q$2/O24*K24,0) -> 0 | V24: =T24*O24 -> 2160 | W24: =O24*U24 -> 0 | X24: {=_xlfn.IFS(P24+Q24>Stock!E24,V24,P24+Q24<Stock!E24,"No need",Stock!E24=0,V24,P24+Q24=Stock!E24,"No need")} -> 2160 | Y24: {=_xlfn.IFS(P24+Q24>Stock!E24,W24,P24+Q24<Stock!E24,"No need",Stock!E24=0,W24,P24+Q24=Stock!E24,"No need")} -> 0 | Z24: {=_xlfn.IFS(ISNUMBER(X24+Y24),X24+Y24,ISTEXT(X24&Y24),"No need")} -> 2160 | AA24: {=_xlfn.IFS(S24*O24>0,S24*O24,S24*O24<0,"No need",S24*O24=0,0)} -> 720
A25: 23 | B25: 9846498180 | C25: Adient Zaragoza | D25: 6201620-0-9 | E25: MECHANICAL LUMBAR HANDWHEEL CAP LH & RH CDPO OPTIMIZED RADIUS | F25: EA | G25: 1 | H25: 1 | I25: 0 | J25: 0 | K25: 0 | L25: 0 | M25: 0 | N25: 0 | O25: 1200 | P25: =G25*$P$2 -> 1488 | Q25: =K25*$Q$2 -> 0 | R25: =(P25+Q25)-Stock!E25 -> -860 | S25: =ROUNDUP(R25/O25,0) -> -1 | T25: =ROUNDUP($P$2/O25*G25,0) -> 2 | U25: =ROUNDUP($Q$2/O25*K25,0) -> 0 | V25: =T25*O25 -> 2400 | W25: =O25*U25 -> 0 | X25: {=_xlfn.IFS(P25+Q25>Stock!E25,V25,P25+Q25<Stock!E25,"No need",Stock!E25=0,V25,P25+Q25=Stock!E25,"No need")} -> No need | Y25: {=_xlfn.IFS(P25+Q25>Stock!E25,W25,P25+Q25<Stock!E25,"No need",Stock!E25=0,W25,P25+Q25=Stock!E25,"No need")} -> No need | Z25: {=_xlfn.IFS(ISNUMBER(X25+Y25),X25+Y25,ISTEXT(X25&Y25),"No need")} -> No need | AA25: {=_xlfn.IFS(S25*O25>0,S25*O25,S25*O25<0,"No need",S25*O25=0,0)} -> No need
A26: 24 | B26: 9824596080 | C26: Adient Zaragoza | D26: 5872481-0-9 | E26: LH HEIGHT ADJUSTER MECHANISM LEVER 2,8° | F26: EA | G26: 1 | H26: 1 | I26: 0 | J26: 0 | K26: 0 | L26: 0 | M26: 0 | N26: 0 | O26: 2480 | P26: =G26*$P$2 -> 1488 | Q26: =K26*$Q$2 -> 0 | R26: =(P26+Q26)-Stock!E26 -> -952 | S26: =ROUNDUP(R26/O26,0) -> -1 | T26: =ROUNDUP($P$2/O26*G26,0) -> 1 | U26: =ROUNDUP($Q$2/O26*K26,0) -> 0 | V26: =T26*O26 -> 2480 | W26: =O26*U26 -> 0 | X26: {=_xlfn.IFS(P26+Q26>Stock!E26,V26,P26+Q26<Stock!E26,"No need",Stock!E26=0,V26,P26+Q26=Stock!E26,"No need")} -> No need | Y26: {=_xlfn.IFS(P26+Q26>Stock!E26,W26,P26+Q26<Stock!E26,"No need",Stock!E26=0,W26,P26+Q26=Stock!E26,"No need")} -> No need | Z26: {=_xlfn.IFS(ISNUMBER(X26+Y26),X26+Y26,ISTEXT(X26&Y26),"No need")} -> No need | AA26: {=_xlfn.IFS(S26*O26>0,S26*O26,S26*O26<0,"No need",S26*O26=0,0)} -> No need
A27: 25 | B27: 9824595680 | C27: Adient Zaragoza | D27: 5872489-0-9 | E27: RH HEIGHT ADJUSTER MECHANISM LEVER 2,8° | F27: EA | G27: 1 | H27: 0 | I27: 1 | J27: 0 | K27: 1 | L27: 0 | M27: 1 | N27: 0 | O27: 2480 | P27: =G27*$P$2 -> 1488 | Q27: =K27*$Q$2 -> 2256 | R27: =(P27+Q27)-Stock!E27 -> -1093 | S27: =ROUNDUP(R27/O27,0) -> -1 | T27: =ROUNDUP($P$2/O27*G27,0) -> 1 | U27: =ROUNDUP($Q$2/O27*K27,0) -> 1 | V27: =T27*O27 -> 2480 | W27: =O27*U27 -> 2480 | X27: {=_xlfn.IFS(P27+Q27>Stock!E27,V27,P27+Q27<Stock!E27,"No need",Stock!E27=0,V27,P27+Q27=Stock!E27,"No need")} -> No need | Y27: {=_xlfn.IFS(P27+Q27>Stock!E27,W27,P27+Q27<Stock!E27,"No need",Stock!E27=0,W27,P27+Q27=Stock!E27,"No need")} -> No need | Z27: {=_xlfn.IFS(ISNUMBER(X27+Y27),X27+Y27,ISTEXT(X27&Y27),"No need")} -> No need | AA27: {=_xlfn.IFS(S27*O27>0,S27*O27,S27*O27<0,"No need",S27*O27=0,0)} -> No need
A28: 26 | B28: 9824525980 | C28: Adient Zaragoza | D28: 4171865-0-9 | E28: LH HEIGHT ADJUSTER LEVER | F28: EA | G28: 1 | H28: 1 | I28: 0 | J28: 0 | K28: 0 | L28: 0 | M28: 0 | N28: 0 | O28: 640 | P28: =G28*$P$2 -> 1488 | Q28: =K28*$Q$2 -> 0 | R28: =(P28+Q28)-Stock!E28 -> 255 | S28: =ROUNDUP(R28/O28,0) -> 1 | T28: =ROUNDUP($P$2/O28*G28,0) -> 3 | U28: =ROUNDUP($Q$2/O28*K28,0) -> 0 | V28: =T28*O28 -> 1920 | W28: =O28*U28 -> 0 | X28: {=_xlfn.IFS(P28+Q28>Stock!E28,V28,P28+Q28<Stock!E28,"No need",Stock!E28=0,V28,P28+Q28=Stock!E28,"No need")} -> 1920 | Y28: {=_xlfn.IFS(P28+Q28>Stock!E28,W28,P28+Q28<Stock!E28,"No need",Stock!E28=0,W28,P28+Q28=Stock!E28,"No need")} -> 0 | Z28: {=_xlfn.IFS(ISNUMBER(X28+Y28),X28+Y28,ISTEXT(X28&Y28),"No need")} -> 1920 | AA28: {=_xlfn.IFS(S28*O28>0,S28*O28,S28*O28<0,"No need",S28*O28=0,0)} -> 640
A29: 27 | B29: 9849854680 | C29: Adient Zaragoza | D29: 4171869-0-9 | E29: RH HEIGHT ADJUSTER LEVER | F29: EA | G29: 1 | H29: 0 | I29: 1 | J29: 0 | K29: 1 | L29: 0 | M29: 1 | N29: 0 | O29: 640 | P29: =G29*$P$2 -> 1488 | Q29: =K29*$Q$2 -> 2256 | R29: =(P29+Q29)-Stock!E29 -> 652 | S29: =ROUNDUP(R29/O29,0) -> 2 | T29: =ROUNDUP($P$2/O29*G29,0) -> 3 | U29: =ROUNDUP($Q$2/O29*K29,0) -> 4 | V29: =T29*O29 -> 1920 | W29: =O29*U29 -> 2560 | X29: {=_xlfn.IFS(P29+Q29>Stock!E29,V29,P29+Q29<Stock!E29,"No need",Stock!E29=0,V29,P29+Q29=Stock!E29,"No need")} -> 1920 | Y29: {=_xlfn.IFS(P29+Q29>Stock!E29,W29,P29+Q29<Stock!E29,"No need",Stock!E29=0,W29,P29+Q29=Stock!E29,"No need")} -> 2560 | Z29: {=_xlfn.IFS(ISNUMBER(X29+Y29),X29+Y29,ISTEXT(X29&Y29),"No need")} -> 4480 | AA29: {=_xlfn.IFS(S29*O29>0,S29*O29,S29*O29<0,"No need",S29*O29=0,0)} -> 1280
A30: 28 | B30: 9824468880 | C30: Adient Zaragoza | D30: 4171380-0-8 | E30: LATCH COVER LH / RH | F30: EA | G30: 0 | H30: 0 | I30: 0 | J30: 0 | K30: 2 | L30: 0 | M30: 0 | N30: 2 | O30: 222 | P30: =G30*$P$2 -> 0 | Q30: =K30*$Q$2 -> 4512 | R30: =(P30+Q30)-Stock!E30 -> 1236 | S30: =ROUNDUP(R30/O30,0) -> 6 | T30: =ROUNDUP($P$2/O30*G30,0) -> 0 | U30: =ROUNDUP($Q$2/O30*K30,0) -> 21 | V30: =T30*O30 -> 0 | W30: =O30*U30 -> 4662 | X30: {=_xlfn.IFS(P30+Q30>Stock!E30,V30,P30+Q30<Stock!E30,"No need",Stock!E30=0,V30,P30+Q30=Stock!E30,"No need")} -> 0 | Y30: {=_xlfn.IFS(P30+Q30>Stock!E30,W30,P30+Q30<Stock!E30,"No need",Stock!E30=0,W30,P30+Q30=Stock!E30,"No need")} -> 4662 | Z30: {=_xlfn.IFS(ISNUMBER(X30+Y30),X30+Y30,ISTEXT(X30&Y30),"No need")} -> 4662 | AA30: {=_xlfn.IFS(S30*O30>0,S30*O30,S30*O30<0,"No need",S30*O30=0,0)} -> 1332
A31: 29 | B31: 9824456680 | C31: Adient Zaragoza | D31: 4171385-0-8 | E31: BELT EXIT COVER | F31: EA | G31: 1 | H31: 0 | I31: 0 | J31: 1 | K31: 1 | L31: 0 | M31: 0 | N31: 1 | O31: 104 | P31: =G31*$P$2 -> 1488 | Q31: =K31*$Q$2 -> 2256 | R31: =(P31+Q31)-Stock!E31 -> 876 | S31: =ROUNDUP(R31/O31,0) -> 9 | T31: =ROUNDUP($P$2/O31*G31,0) -> 15 | U31: =ROUNDUP($Q$2/O31*K31,0) -> 22 | V31: =T31*O31 -> 1560 | W31: =O31*U31 -> 2288 | X31: {=_xlfn.IFS(P31+Q31>Stock!E31,V31,P31+Q31<Stock!E31,"No need",Stock!E31=0,V31,P31+Q31=Stock!E31,"No need")} -> 1560 | Y31: {=_xlfn.IFS(P31+Q31>Stock!E31,W31,P31+Q31<Stock!E31,"No need",Stock!E31=0,W31,P31+Q31=Stock!E31,"No need")} -> 2288 | Z31: {=_xlfn.IFS(ISNUMBER(X31+Y31),X31+Y31,ISTEXT(X31&Y31),"No need")} -> 3848 | AA31: {=_xlfn.IFS(S31*O31>0,S31*O31,S31*O31<0,"No need",S31*O31=0,0)} -> 936
A32: 30 | B32: 9836802180 | C32: Adient Zaragoza | D32: 4171388-0-8 | E32: LATERAL OUTER PIVOT BRACKET COVER LH | F32: EA | G32: 1 | H32: 0 | I32: 0 | J32: 1 | K32: 1 | L32: 0 | M32: 0 | N32: 1 | O32: 108 | P32: =G32*$P$2 -> 1488 | Q32: =K32*$Q$2 -> 2256 | R32: =(P32+Q32)-Stock!E32 -> 861 | S32: =ROUNDUP(R32/O32,0) -> 8 | T32: =ROUNDUP($P$2/O32*G32,0) -> 14 | U32: =ROUNDUP($Q$2/O32*K32,0) -> 21 | V32: =T32*O32 -> 1512 | W32: =O32*U32 -> 2268 | X32: {=_xlfn.IFS(P32+Q32>Stock!E32,V32,P32+Q32<Stock!E32,"No need",Stock!E32=0,V32,P32+Q32=Stock!E32,"No need")} -> 1512 | Y32: {=_xlfn.IFS(P32+Q32>Stock!E32,W32,P32+Q32<Stock!E32,"No need",Stock!E32=0,W32,P32+Q32=Stock!E32,"No need")} -> 2268 | Z32: {=_xlfn.IFS(ISNUMBER(X32+Y32),X32+Y32,ISTEXT(X32&Y32),"No need")} -> 3780 | AA32: {=_xlfn.IFS(S32*O32>0,S32*O32,S32*O32<0,"No need",S32*O32=0,0)} -> 864
A33: 31 | B33: 9836802780 | C33: Adient Zaragoza | D33: 4171389-0-8 | E33: LATERAL OUTER PIVOT BRACKET COVER RH | F33: EA | G33: 1 | H33: 0 | I33: 0 | J33: 1 | K33: 1 | L33: 0 | M33: 0 | N33: 1 | O33: 108 | P33: =G33*$P$2 -> 1488 | Q33: =K33*$Q$2 -> 2256 | R33: =(P33+Q33)-Stock!E33 -> 861 | S33: =ROUNDUP(R33/O33,0) -> 8 | T33: =ROUNDUP($P$2/O33*G33,0) -> 14 | U33: =ROUNDUP($Q$2/O33*K33,0) -> 21 | V33: =T33*O33 -> 1512 | W33: =O33*U33 -> 2268 | X33: {=_xlfn.IFS(P33+Q33>Stock!E33,V33,P33+Q33<Stock!E33,"No need",Stock!E33=0,V33,P33+Q33=Stock!E33,"No need")} -> 1512 | Y33: {=_xlfn.IFS(P33+Q33>Stock!E33,W33,P33+Q33<Stock!E33,"No need",Stock!E33=0,W33,P33+Q33=Stock!E33,"No need")} -> 2268 | Z33: {=_xlfn.IFS(ISNUMBER(X33+Y33),X33+Y33,ISTEXT(X33&Y33),"No need")} -> 3780 | AA33: {=_xlfn.IFS(S33*O33>0,S33*O33,S33*O33<0,"No need",S33*O33=0,0)} -> 864
A34: 32 | B34: 9824521280 | C34: Adient Zaragoza | D34: 4171741-0-9 | E34: LH - SIDE COVER - 4WP+2WM LEFT POWER + LUMBAR | F34: EA | G34: 0 | H34: 0 | I34: 0 | J34: 0 | K34: 1 | L34: 1 | M34: 0 | N34: 0 | O34: 100 | P34: =G34*$P$2 -> 0 | Q34: =K34*$Q$2 -> 2256 | R34: =(P34+Q34)-Stock!E34 -> 518 | S34: =ROUNDUP(R34/O34,0) -> 6 | T34: =ROUNDUP($P$2/O34*G34,0) -> 0 | U34: =ROUNDUP($Q$2/O34*K34,0) -> 23 | V34: =T34*O34 -> 0 | W34: =O34*U34 -> 2300 | X34: {=_xlfn.IFS(P34+Q34>Stock!E34,V34,P34+Q34<Stock!E34,"No need",Stock!E34=0,V34,P34+Q34=Stock!E34,"No need")} -> 0 | Y34: {=_xlfn.IFS(P34+Q34>Stock!E34,W34,P34+Q34<Stock!E34,"No need",Stock!E34=0,W34,P34+Q34=Stock!E34,"No need")} -> 2300 | Z34: {=_xlfn.IFS(ISNUMBER(X34+Y34),X34+Y34,ISTEXT(X34&Y34),"No need")} -> 2300 | AA34: {=_xlfn.IFS(S34*O34>0,S34*O34,S34*O34<0,"No need",S34*O34=0,0)} -> 600
A35: 33 | B35: 9824488680 | C35: Adient Zaragoza | D35: 4171746-0-9 | E35: RH - SIDE COVER - 6WAY MANUAL W/ POWER + LUMBAR HYBRID | F35: EA | G35: 0 | H35: 0 | I35: 0 | J35: 0 | K35: 1 | L35: 0 | M35: 1 | N35: 0 | O35: 100 | P35: =G35*$P$2 -> 0 | Q35: =K35*$Q$2 -> 2256 | R35: =(P35+Q35)-Stock!E35 -> 511 | S35: =ROUNDUP(R35/O35,0) -> 6 | T35: =ROUNDUP($P$2/O35*G35,0) -> 0 | U35: =ROUNDUP($Q$2/O35*K35,0) -> 23 | V35: =T35*O35 -> 0 | W35: =O35*U35 -> 2300 | X35: {=_xlfn.IFS(P35+Q35>Stock!E35,V35,P35+Q35<Stock!E35,"No need",Stock!E35=0,V35,P35+Q35=Stock!E35,"No need")} -> 0 | Y35: {=_xlfn.IFS(P35+Q35>Stock!E35,W35,P35+Q35<Stock!E35,"No need",Stock!E35=0,W35,P35+Q35=Stock!E35,"No need")} -> 2300 | Z35: {=_xlfn.IFS(ISNUMBER(X35+Y35),X35+Y35,ISTEXT(X35&Y35),"No need")} -> 2300 | AA35: {=_xlfn.IFS(S35*O35>0,S35*O35,S35*O35<0,"No need",S35*O35=0,0)} -> 600
A36: 34 | B36: 9835223780 | C36: Adient Zaragoza | D36: 5324015-0-8 | E36: ARMREST END STOP BRACKET LH | F36: EA | G36: 0 | H36: 0 | I36: 0 | J36: 0 | K36: 1 | L36: 0 | M36: 0 | N36: 1 | O36: 1000 | P36: =G36*$P$2 -> 0 | Q36: =K36*$Q$2 -> 2256 | R36: =(P36+Q36)-Stock!E36 -> 123 | S36: =ROUNDUP(R36/O36,0) -> 1 | T36: =ROUNDUP($P$2/O36*G36,0) -> 0 | U36: =ROUNDUP($Q$2/O36*K36,0) -> 3 | V36: =T36*O36 -> 0 | W36: =O36*U36 -> 3000 | X36: {=_xlfn.IFS(P36+Q36>Stock!E36,V36,P36+Q36<Stock!E36,"No need",Stock!E36=0,V36,P36+Q36=Stock!E36,"No need")} -> 0 | Y36: {=_xlfn.IFS(P36+Q36>Stock!E36,W36,P36+Q36<Stock!E36,"No need",Stock!E36=0,W36,P36+Q36=Stock!E36,"No need")} -> 3000 | Z36: {=_xlfn.IFS(ISNUMBER(X36+Y36),X36+Y36,ISTEXT(X36&Y36),"No need")} -> 3000 | AA36: {=_xlfn.IFS(S36*O36>0,S36*O36,S36*O36<0,"No need",S36*O36=0,0)} -> 1000
A37: 35 | B37: 9835223380 | C37: Adient Zaragoza | D37: 5324123-0-8 | E37: ARMREST END STOP BRACKET RH | F37: EA | G37: 0 | H37: 0 | I37: 0 | J37: 0 | K37: 1 | L37: 0 | M37: 0 | N37: 1 | O37: 1000 | P37: =G37*$P$2 -> 0 | Q37: =K37*$Q$2 -> 2256 | R37: =(P37+Q37)-Stock!E37 -> 123 | S37: =ROUNDUP(R37/O37,0) -> 1 | T37: =ROUNDUP($P$2/O37*G37,0) -> 0 | U37: =ROUNDUP($Q$2/O37*K37,0) -> 3 | V37: =T37*O37 -> 0 | W37: =O37*U37 -> 3000 | X37: {=_xlfn.IFS(P37+Q37>Stock!E37,V37,P37+Q37<Stock!E37,"No need",Stock!E37=0,V37,P37+Q37=Stock!E37,"No need")} -> 0 | Y37: {=_xlfn.IFS(P37+Q37>Stock!E37,W37,P37+Q37<Stock!E37,"No need",Stock!E37=0,W37,P37+Q37=Stock!E37,"No need")} -> 3000 | Z37: {=_xlfn.IFS(ISNUMBER(X37+Y37),X37+Y37,ISTEXT(X37&Y37),"No need")} -> 3000 | AA37: {=_xlfn.IFS(S37*O37>0,S37*O37,S37*O37<0,"No need",S37*O37=0,0)} -> 1000
A38: 36 | B38: N/A | C38: Adient Zaragoza | D38: 4795975-0-8 | E38: SKILID FRT COVER ASM | F38: EA | G38: 0 | H38: 0 | I38: 0 | J38: 0 | K38: 1 | L38: 0 | M38: 0 | N38: 1 | O38: 126 | P38: =G38*$P$2 -> 0 | Q38: =K38*$Q$2 -> 2256 | R38: =(P38+Q38)-Stock!E38 -> -2180 | S38: =ROUNDUP(R38/O38,0) -> -18 | T38: =ROUNDUP($P$2/O38*G38,0) -> 0 | U38: =ROUNDUP($Q$2/O38*K38,0) -> 18 | V38: =T38*O38 -> 0 | W38: =O38*U38 -> 2268 | X38: {=_xlfn.IFS(P38+Q38>Stock!E38,V38,P38+Q38<Stock!E38,"No need",Stock!E38=0,V38,P38+Q38=Stock!E38,"No need")} -> No need | Y38: {=_xlfn.IFS(P38+Q38>Stock!E38,W38,P38+Q38<Stock!E38,"No need",Stock!E38=0,W38,P38+Q38=Stock!E38,"No need")} -> No need | Z38: {=_xlfn.IFS(ISNUMBER(X38+Y38),X38+Y38,ISTEXT(X38&Y38),"No need")} -> No need | AA38: {=_xlfn.IFS(S38*O38>0,S38*O38,S38*O38<0,"No need",S38*O38=0,0)} -> No need
A39: 37 | B39: N/A | C39: Adient Zaragoza | D39: 4170935-0-8 | E39: SKILID REAR COVER | F39: EA | G39: 0 | H39: 0 | I39: 0 | J39: 0 | K39: 1 | L39: 0 | M39: 0 | N39: 1 | O39: 396 | P39: =G39*$P$2 -> 0 | Q39: =K39*$Q$2 -> 2256 | R39: =(P39+Q39)-Stock!E39 -> 343 | S39: =ROUNDUP(R39/O39,0) -> 1 | T39: =ROUNDUP($P$2/O39*G39,0) -> 0 | U39: =ROUNDUP($Q$2/O39*K39,0) -> 6 | V39: =T39*O39 -> 0 | W39: =O39*U39 -> 2376 | X39: {=_xlfn.IFS(P39+Q39>Stock!E39,V39,P39+Q39<Stock!E39,"No need",Stock!E39=0,V39,P39+Q39=Stock!E39,"No need")} -> 0 | Y39: {=_xlfn.IFS(P39+Q39>Stock!E39,W39,P39+Q39<Stock!E39,"No need",Stock!E39=0,W39,P39+Q39=Stock!E39,"No need")} -> 2376 | Z39: {=_xlfn.IFS(ISNUMBER(X39+Y39),X39+Y39,ISTEXT(X39&Y39),"No need")} -> 2376 | AA39: {=_xlfn.IFS(S39*O39>0,S39*O39,S39*O39<0,"No need",S39*O39=0,0)} -> 396
A40: 38 | B40: N/A | C40: Adient Zaragoza | D40: 4232969-0-8 | E40: SKILID SUPPORT PLATE | F40: EA | G40: 0 | H40: 0 | I40: 0 | J40: 0 | K40: 1 | L40: 0 | M40: 0 | N40: 1 | O40: 218 | P40: =G40*$P$2 -> 0 | Q40: =K40*$Q$2 -> 2256 | R40: =(P40+Q40)-Stock!E40 -> 361 | S40: =ROUNDUP(R40/O40,0) -> 2 | T40: =ROUNDUP($P$2/O40*G40,0) -> 0 | U40: =ROUNDUP($Q$2/O40*K40,0) -> 11 | V40: =T40*O40 -> 0 | W40: =O40*U40 -> 2398 | X40: {=_xlfn.IFS(P40+Q40>Stock!E40,V40,P40+Q40<Stock!E40,"No need",Stock!E40=0,V40,P40+Q40=Stock!E40,"No need")} -> 0 | Y40: {=_xlfn.IFS(P40+Q40>Stock!E40,W40,P40+Q40<Stock!E40,"No need",Stock!E40=0,W40,P40+Q40=Stock!E40,"No need")} -> 2398 | Z40: {=_xlfn.IFS(ISNUMBER(X40+Y40),X40+Y40,ISTEXT(X40&Y40),"No need")} -> 2398 | AA40: {=_xlfn.IFS(S40*O40>0,S40*O40,S40*O40<0,"No need",S40*O40=0,0)} -> 436
...

Sheet Stock
A2: Serial | B2: STL PN | C2: ADIENT PN | D2: DESCRIPTION | E2: Final Stock
A3: 1 | B3: 9823868480 | C3: 4207718-0-9 | D3: MANUAL - FRONT RIGHT SEAT BACKREST FRAME | E3: 2846
A4: 2 | B4: 9823868180 | C4: 4812333-0-9 | D4: POWER - FRONT SEAT LEFT / RIGHT BACKREST FRAME - NON MEMO | E4: 1689
A5: 3 | B5: 9823868280 | C5: 4207618-0-9 | D5: MANUAL - FRONT LEFT SEAT BACKREST FRAME | E5: 1165
A6: 4 | B6: 9832027580 | C6: 4355899-0-9 | D6: 6WAY MANUAL - FRONT LHD PASSANGER SEAT CUSHION FRAME 6WAY MANUAL - FRONT RHD DRIVER SEAT CUSHION FRAME | E6: 2838
A7: 5 | B7: 9832021380 | C7: 4812346-0-9 | D7: 6WAY HYBRID - FRONT LHD DRIVER SEAT CUSHION FRAME | E7: 1692
A8: 6 | B8: 9832021180 | C8: 4207871-0-9 | D8: 6WAY MANUAL - FRONT LHD DRIVER SEAT CUSHION FRAME 6WAY MANUAL - FRONT RHD PASSENGER SEAT CUSHION FRAME | E8: 1161
A9: 7 | B9: 9833400580 | C9: 4171294-0-8 | D9: REAR SEAT BACKREST FRAME 40% | E9: 2849
A10: 8 | B10: 9833208180 | C10: 4171342-0-8 | D10: REAR SEAT BACKREST FRAME 60% W/ ARMREST | E10: 1692
A11: 9 | B11: 9833208280 | C11: 4171338-0-8 | D11: REAR SEAT BACKREST FRAME 60% W/O ARMREST | E11: 1157
A12: 10 | B12: 9814491980 | C12: 4171343-0-8 | D12: LATCH RH 40% | E12: 3077
A13: 11 | B13: 9814492580 | C13: 4171348-0-8 | D13: LATCH LH 60% | E13: 3071
A14: 12 | B14: 9818614480 | C14: 4171684-0-9 | D14: GUIDE APPUI-TETE SIEGE AV G (LISSE) FRONT - NON LOCKING BEZEL | E14: 8400
A15: 13 | B15: 9818614580 | C15: 4171687-0-9 | D15: FRONT - LOCKING BEZEL | E15: 8410
A16: 14 | B16: 9811628680 | C16: 4171695-0-9 | D16: TRACK END CAP | E16: 11800
A17: 15 | B17: 9824492180 | C17: 4171702-0-9 | D17: LH - SIDE COVER - 6WAY MANUAL | E17: 1423
A18: 16 | B18: 9824487880 | C18: 4171705-0-9 | D18: RH - SIDE COVER - 6WAY MANUAL | E18: 1425
A19: 17 | B19: 9824523980 | C19: 4171756-0-9 | D19: RECLINER INNER COVER - LH | E19: 2950
A20: 18 | B20: 9824522580 | C20: 4171759-0-9 | D20: RECLINER INNER COVER - RH | E20: 2948
A21: 19 | B21: 9825038780 | C21: 4171763-0-9 | D21: RECLINER HANDWHEEL - HARD | E21: 2405
A22: 33 | B22: 9825048280 | C22: 5222357-0-9 | D22: RECLINER HANDWHEEL - SOFT | E22: 1745
A23: 20 | B23: 9825013880 | C23: 4171767-0-9 | D23: RECLINER HANDWHEEL CAP | E23: 1704
A24: 21 | B24: 9846498080 | C24: 6201578-0-9 | D24: MECHANICAL LUMBAR HANDWHEEL LH & RH CDPO OPTIMIZED RADIUS | E24: 1390
A25: 22 | B25: 9846498180 | C25: 6201620-0-9 | D25: MECHANICAL LUMBAR HANDWHEEL CAP LH & RH CDPO OPTIMIZED RADIUS | E25: 2348
A26: 23 | B26: 9824596080 | C26: 5872481-0-9 | D26: LH HEIGHT ADJUSTER MECHANISM LEVER 2,8° | E26: 2440
A27: 24 | B27: 9824595680 | C27: 5872489-0-9 | D27: RH HEIGHT ADJUSTER MECHANISM LEVER 2,8° | E27: 4837
A28: 25 | B28: 9824525980 | C28: 4171865-0-9 | D28: LH HEIGHT ADJUSTER LEVER | E28: 1233
A29: 26 | B29: 9849854680 | C29: 4171869-0-9 | D29: RH HEIGHT ADJUSTER LEVER | E29: 3092
A30: 27 | B30: 9824468880 | C30: 4171380-0-8 | D30: LATCH COVER LH / RH | E30: 3276
A31: 28 | B31: 9824456680 | C31: 4171385-0-8 | D31: BELT EXIT COVER | E31: 2868
A32: 29 | B32: 9836802180 | C32: 4171388-0-8 | D32: LATERAL OUTER PIVOT BRACKET COVER LH | E32: 2883
A33: 30 | B33: 9836802780 | C33: 4171389-0-8 | D33: LATERAL OUTER PIVOT BRACKET COVER RH | E33: 2883
A34: 31 | B34: 9824521280 | C34: 4171741-0-9 | D34: LH - SIDE COVER - 4WP+2WM LEFT POWER + LUMBAR | E34: 1738
A35: 32 | B35: 9824488680 | C35: 4171746-0-9 | D35: RH - SIDE COVER - 6WAY MANUAL W/ POWER + LUMBAR HYBRID | E35: 1745
A36: 34 | B36: 9835223780 | C36: 5324015-0-8 | D36: ARMREST END STOP BRACKET LH | E36: 2133
A37: 35 | B37: 9835223380 | C37: 5324123-0-8 | D37: ARMREST END STOP BRACKET RH | E37: 2133
A38: 36 | B38: N/A | C38: 4795975-0-8 | D38: SKILID FRT COVER ASM | E38: 4436
A39: 37 | B39: N/A | C39: 4170935-0-8 | D39: SKILID REAR COVER | E39: 1913
A40: 38 | B40: N/A | C40: 4232969-0-8 | D40: SKILID SUPPORT PLATE | E40: 1895
A41: 39 | B41: 9862718380 | C41: 6157189-E3P-9 | D41: FRONT SEAT HEADREST LH & RH - ML L3opt MANHATTEN HORIZON 10C | E41: 3408
...

Sheet Local and semi finished
F1: =48*6 -> 288 | G1: =48*8 -> 384
A2: SAP | B2: Descrbtion | C2: EA/M | D2: L2 cons | E2: L3 cons | F2: Units L2 | G2: Units L3 | H2: Total
A3: AML-WIR-Uzig-110 | B3: سلك حرف U متعرج 110 | C3: EA | D3: 2 | E3: 2 | F3: =$F$1*D3 -> 576 | G3: =$G$1*E3 -> 768 | H3: =G3+F3 -> 1344
A4: AML-WIR-Uzig-120 | B4: سلك حرف U متعرج 120 | C4: EA | D4: 2 | E4: 2 | F4: =$F$1*D4 -> 576 | G4: =$G$1*E4 -> 768 | H4: =G4+F4 -> 1344
A5: AML-WIR-Uzig-115 | B5: سلك حرف U متعرج سيتروين 115 | C5: EA | D5: 2 | E5: 2 | F5: =$F$1*D5 -> 576 | G5: =$G$1*E5 -> 768 | H5: =G5+F5 -> 1344
A6: AML-WIR-Uzig-125 | B6: سلك حرف U متعرج 125 | C6: EA | D6: 2 | E6: 2 | F6: =$F$1*D6 -> 576 | G6: =$G$1*E6 -> 768 | H6: =G6+F6 -> 1344
A7: AML-WIR-030 | B7: سلك مقاس 30 | C7: EA | D7: 4 | E7: 4 | F7: =$F$1*D7 -> 1152 | G7: =$G$1*E7 -> 1536 | H7: =G7+F7 -> 2688
A8: AML-WIR-024 | B8: سلك مقاس 24 | C8: EA | D8: 1 | E8: 1 | F8: =$F$1*D8 -> 288 | G8: =$G$1*E8 -> 384 | H8: =G8+F8 -> 672
A9: AML-WIR-020 | B9: سلك مقاس 20 | C9: EA | D9: 2 | E9: 2 | F9: =$F$1*D9 -> 576 | G9: =$G$1*E9 -> 768 | H9: =G9+F9 -> 1344
A10: AML-FBRDC-0001-00 | B10: داكرون | C10: KG | D10: 0.6 | E10: 0.6 | F10: =$F$1*D10 -> 172.8 | G10: =$G$1*E10 -> 230.4 | H10: =G10+F10 -> 403.2
A14: Foam | F14: =2*48 -> 96 | G14: =3*48 -> 144
A15: SAP | B15: Descrbtion ENG | C15: Descrbtion AR | D15: L2 cons | E15: L3 cons | F15: Units L2 | G15: Units L3 | H15: Total
A16: ASF-CIT-C43-FO01 | B16: Foam front back RH Citroen C43 | C16: فوم ظهرأمامي يمين سيتروين C43 | D16: 1 | E16: 1 | F16: =$F$14*D16 -> 96 | G16: =$G$14*E16 -> 144 | H16: =F16+G16 -> 240
A17: ASF-CIT-C43-FO02 | B17: Foam front back LH Citroen C43 | C17: فوم ظهرأمامي شمال سيتروين C43 | D17: 1 | E17: 1 | F17: =$F$14*D17 -> 96 | G17: =$G$14*E17 -> 144 | H17: =F17+G17 -> 240
A18: ASF-CIT-C43-FO03 | B18: Foam front cushion RH Citroen C43 | C18: فوم قاعدة أمامي يمين سيتروين C43 | D18: 1 | E18: 1 | F18: =$F$14*D18 -> 96 | G18: =$G$14*E18 -> 144 | H18: =F18+G18 -> 240
A19: ASF-CIT-C43-FO04 | B19: Foam front cushion LH Citroen C43 | C19: فوم قاعدة أمامي شمال سيتروين C43 | D19: 1 | E19: 1 | F19: =$F$14*D19 -> 96 | G19: =$G$14*E19 -> 144 | H19: =F19+G19 -> 240
A20: ASF-CIT-C43-FO05 | B20: Foam back 40% Citroen C43 | C20: فوم ظهر 40% سيتروين C43 | D20: 1 | E20: 1 | F20: =$F$14*D20 -> 96 | G20: =$G$14*E20 -> 144 | H20: =F20+G20 -> 240
A21: ASF-CIT-C43L3-FO06 | B21: Foam back 60% Citroen C43 Lvl 3 | C21: فوم ظهر 60% سيتروين C43 Lvl 3 | D21: 0 | E21: 1 | F21: =$F$14*D21 -> 0 | G21: =$G$14*E21 -> 144 | H21: =F21+G21 -> 144
A22: ASF-CIT-C43L2-FO06 | B22: Citroen Foam C43 Lvl 2 back 60% | C22: فوم سيتروينC43 Lvl 2 ظهر 60% | D22: 1 | E22: 0 | F22: =$F$14*D22 -> 96 | G22: =$G$14*E22 -> 0 | H22: =F22+G22 -> 96
A23: ASF-CIT-C43-FO07 | B23: Foam cushion 100% Citroen C43 | C23: فوم قاعدة خلفي 100% سيتروين C43 | D23: 1 | E23: 1 | F23: =$F$14*D23 -> 96 | G23: =$G$14*E23 -> 144 | H23: =F23+G23 -> 240
A26: SAP | B26: Descrbtion ENG | C26: Descrbtion AR | D26: L2 cons | E26: L3 cons | F26: Units L2 | G26: Units L3 | H26: Total
A27: ASF-CIT-C43L3-CH01 | B27: Chassis Insert Cushion100% Citroen C43L3 | C27: شاسيه 100% قاعدة سيتروين Lvl 3 | D27: 0 | E27: 1 | F27: =$F$14*D27 -> 0 | G27: =$G$14*E27 -> 144 | H27: =G27+F27 -> 144
A28: ASF-CIT-C43L2-CH01 | B28: Chassis Insert Cushion100% Citroen C43L2 | C28: شاسيه 100% قاعدة سيتروين Lvl 2 | D28: 1 | E28: 0 | F28: =$F$14*D28 -> 96 | G28: =$G$14*E28 -> 0 | H28: =G28+F28 -> 96
A30: Trim covers
A31: SAP | B31: Descrbtion ENG | C31: Descrbtion AR | D31: L2 cons | E31: L3 cons | F31: Units L2 | G31: Units L3 | H31: Total
A32: ASF-C43-L3-TC3-01 | B32: Trim cover Front cushion RH C43 Lvl 3 | C32: كسوة قاعدة أمامي يمين Lvl 3 C43 | D32: 0 | E32: 1 | F32: =$F$30*D32 -> 0 | G32: =$G$30*E32 -> 0 | H32: =G32+F32 -> 0
A33: ASF-C43-L3-TC4-01 | B33: Trim cover Front cushion LH C43 Lvl 3 | C33: كسوة قاعدة أمامي شمال Lvl 3 C43 | D33: 0 | E33: 1 | F33: =$F$30*D33 -> 0 | G33: =$G$30*E33 -> 0 | H33: =G33+F33 -> 0
A34: ASF-C43-L3-TC5-01 | B34: Trim cover back 40% C43 Lvl 3 white | C34: كسوة ظهر 40% Lvl 3 C43 | D34: 0 | E34: 1 | F34: =$F$30*D34 -> 0 | G34: =$G$30*E34 -> 0 | H34: =G34+F34 -> 0
A35: ASF-C43-L3-TC6-01 | B35: Trim cover back 60% C43 Lvl 3 white | C35: كسوة ظهر 60% Lvl 3 C43 | D35: 0 | E35: 1 | F35: =$F$30*D35 -> 0 | G35: =$G$30*E35 -> 0 | H35: =G35+F35 -> 0
A36: ASF-C43-L3-TC7-01 | B36: Trim cover cushion 100% C43 Lvl 3 white | C36: كسوة قاعدة 100% Lvl 3 C43 | D36: 0 | E36: 1 | F36: =$F$30*D36 -> 0 | G36: =$G$30*E36 -> 0 | H36: =G36+F36 -> 0
A37: ASF-C43-L2-TC4-90 | B37: Trim cover Front cushion RH C43 Lvl2 | C37: كسوة قاعدة أمامي يمين Lvl 2 C43 اسود | D37: 1 | E37: 0 | F37: =$F$30*D37 -> 0 | G37: =$G$30*E37 -> 0 | H37: =G37+F37 -> 0
A38: ASF-C43-L2-TC5-90 | B38: Trim cover Front cushion LH C43 Lvl2 | C38: كسوة قاعدة أمامي شمال Lvl 2 C43 اسود | D38: 1 | E38: 0 | F38: =$F$30*D38 -> 0 | G38: =$G$30*E38 -> 0 | H38: =G38+F38 -> 0
A39: ASF-C43-L2-TC6-90 | B39: Trim cover back 40% C43 Lvl 2 Black | C39: كسوة ظهر 40% Lvl 2 C43 اسود | D39: 1 | E39: 0 | F39: =$F$30*D39 -> 0 | G39: =$G$30*E39 -> 0 | H39: =G39+F39 -> 0
A40: ASF-C43-L2-TC7-90 | B40: Trim cover back 60% C43 Lvl 2 Black | C40: كسوة ظهر 60% Lvl 2 C43 اسود | D40: 1 | E40: 0 | F40: =$F$30*D40 -> 0 | G40: =$G$30*E40 -> 0 | H40: =G40+F40 -> 0
A41: ASF-C43-L2-TC8-90 | B41: Trim cover cushion 100% C43 Lvl 2 Black | C41: كسوة قاعدة 100% Lvl 2 C43 اسود | D41: 1 | E41: 0 | F41: =$F$30*D41 -> 0 | G41: =$G$30*E41 -> 0 | H41: =G41+F41 -> 0

Sheet 2025 Time plan- not updated
E2: 2025
E3: JANUARY | F3: FEBRUARY | I3: MARCH | J3: APRIL | K3: MAY | L3: JUNE | M3: JULY | N3: AUGUST | O3: SEPTEMBER | P3: OCTOBER | Q3: NOVEMBER | R3: DECEMBER
B4: Monthly Volume | E4: 26 | F4: 30 | I4: 275 | J4: 243 | K4: 260 | L4: 357 | M4: 847 | N4: 850 | O4: 1030 | P4: 808 | Q4: 778 | R4: 990
B5: Cumulative Volume | E5: 26 | F5: 56 | I5: 331 | J5: 574 | K5: 834 | L5: 1191 | M5: 2037 | N5: 2887 | O5: 3917 | P5: 4725 | Q5: 5503 | R5: 6493
D6: Before SOP | G6: After SOP
B7: Level | G7: Level MIX
B8: Level 2 | D8: MIX rule not respected | E8: 14 | F8: 12 | G8: 0.4 | I8: 110 | J8: 97 | K8: 104 | L8: 143 | M8: 339 | N8: 340 | O8: 412 | P8: 323 | Q8: 311 | R8: 396
B9: Level 3 | E9: 12 | F9: 18 | G9: 0.6 | I9: 165 | J9: 148 | K9: 155 | L9: 214 | M9: 508 | N9: 510 | O9: 618 | P9: 485 | Q9: 467 | R9: 594
E10: 26 | F10: 30 | I10: 275 | J10: 245 | K10: 259 | L10: 357 | M10: 847 | N10: 850 | O10: 1030 | P10: 808 | Q10: 778 | R10: 990
I11: =I10+J10 -> 520 | K11: =K10+L10 -> 616
I12: March and April | J12: L2 | K12: =J8+I8 -> 207 | P12: L2 | Q12: L3 Opt.
J13: L3 OPT | K13: =J9+I9 -> 313 | L13: =K11+I11 -> 1136 | P13: =(I8+J8)-(I25+J25) -> 74.2 | Q13: =(I9+J9)-(I26+J26) -> 113.8
J14: L2 | K14: =K8+L8 -> 247
J15: L3 OPT | K15: =K9+L9 -> 369
O17: =I11+K11 -> 1136
E19: 2025
E20: JANUARY | F20: FEBRUARY | I20: MARCH | J20: APRIL | K20: MAY | L20: JUNE | M20: JULY | N20: AUGUST | O20: SEPTEMBER | P20: OCTOBER | Q20: NOVEMBER | R20: DECEMBER | T20: PIV sample | U20: QTY
B21: Monthly Volume | E21: 26 | F21: 30 | I21: 275 | J21: 243 | K21: 260 | L21: 357 | M21: 847 | N21: 850 | O21: 1030 | P21: 808 | Q21: 778 | R21: 990 | T21: C43 MOBICA Driver Seat 6WM LHD, L2, FABRIC TEP | U21: 12
B22: Cumulative Volume | E22: 26 | F22: 56 | I22: 331 | J22: 574 | K22: 834 | L22: 1191 | M22: 2037 | N22: 2887 | O22: 3917 | P22: 4725 | Q22: 5503 | R22: 6493 | T22: C43 MOBICA Driver Seat 6WM LHD, L3 opt ALCANTARA / FABRIC | U22: 5
D23: Before SOP | G23: After SOP | T23: C43 MOBICA Rear Seat, L2, FABRIC TEP | U23: 4
B24: Level | G24: Level MIX | T24: C43 MOBICA Rear Seat, L3 opt ALCANTARA / FABRIC | U24: 4
B25: Level 2 | D25: MIX rule not respected | E25: 14 | F25: 12 | G25: 0.4 | I25: =I27*G25 -> 33.6 | J25: =G25*J27 -> 99.2 | K25: =K27*G25 -> 104 | L25: =G25*L27 -> 140.4 | M25: 339 | N25: 340 | O25: 412 | P25: 323 | Q25: 311 | R25: 396 | T25: C43 MOBICA Passenger Seat 6WM LHD, L2 , FABRIC TEP | U25: 3
B26: Level 3 | E26: 12 | F26: 18 | G26: 0.6 | I26: =G26*I27 -> 50.4 | J26: =J27*G26 -> 148.8 | K26: =K27*G26 -> 156 | L26: =G26*L27 -> 210.6 | M26: 508 | N26: 510 | O26: 618 | P26: 485 | Q26: 467 | R26: 594 | T26: C43 MOBICA Passenger Seat 6WM LHD, L3 opt ALCANTARA / FABRIC | U26: 2
E27: 26 | F27: 30 | I27: 84 | J27: 248 | K27: 260 | L27: 351 | M27: 847 | N27: 850 | O27: 1030 | P27: 808 | Q27: 778 | R27: 990
I28: =I27+J27 -> 332 | K28: =K27+L27 -> 611
R29: New L2 | S29: =(K25+L25)-P13 -> 170.2
M30: =K25+L25 -> 244.4 | R30: New L3 Opt | S30: =(K26+L26)-Q13 -> 252.8
F31: 454 | G31: 377 | H31: 207 | I31: =G31-H31 -> 170 | K31: =I28+K28 -> 943 | M31: =K26+L26 -> 366.6 | N31: =O17-K31 -> 193
F32: 682 | G32: 566 | H32: 313 | I32: =G32-H32 -> 253 | Q32: =260-114 -> 146
Q33: =351-74 -> 277
Q35: =Q32+Q33 -> 423

Sheet local
A1: Purchasing
F3: =48*6 -> 288 | G3: =48*8 -> 384
A4: SAP | B4: Descrbtion | C4: EA/M | D4: L2 cons | E4: L3 cons | F4: Units L2 | G4: Units L3 | H4: Total
A5: AML-WIR-Uzig-110 | B5: سلك حرف U متعرج 110 | C5: EA | D5: 2 | E5: 2 | F5: =$F$3*D5 -> 576 | G5: =$G$3*E5 -> 768 | H5: =G5+F5 -> 1344
A6: AML-WIR-Uzig-120 | B6: سلك حرف U متعرج 120 | C6: EA | D6: 2 | E6: 2 | F6: =$F$3*D6 -> 576 | G6: =$G$3*E6 -> 768 | H6: =G6+F6 -> 1344
A7: AML-WIR-Uzig-115 | B7: سلك حرف U متعرج سيتروين 115 | C7: EA | D7: 2 | E7: 2 | F7: =$F$3*D7 -> 576 | G7: =$G$3*E7 -> 768 | H7: =G7+F7 -> 1344
A8: AML-WIR-Uzig-125 | B8: سلك حرف U متعرج 125 | C8: EA | D8: 2 | E8: 2 | F8: =$F$3*D8 -> 576 | G8: =$G$3*E8 -> 768 | H8: =G8+F8 -> 1344
A9: AML-WIR-030 | B9: سلك مقاس 30 | C9: EA | D9: 4 | E9: 4 | F9: =$F$3*D9 -> 1152 | G9: =$G$3*E9 -> 1536 | H9: =G9+F9 -> 2688
A10: AML-WIR-024 | B10: سلك مقاس 24 | C10: EA | D10: 1 | E10: 1 | F10: =$F$3*D10 -> 288 | G10: =$G$3*E10 -> 384 | H10: =G10+F10 -> 672
A11: AML-WIR-020 | B11: سلك مقاس 20 | C11: EA | D11: 2 | E11: 2 | F11: =$F$3*D11 -> 576 | G11: =$G$3*E11 -> 768 | H11: =G11+F11 -> 1344
A12: AML-FBRDC-0001-00 | B12: داكرون | C12: KG | D12: 0.6 | E12: 0.6 | F12: =$F$3*D12 -> 172.8 | G12: =$G$3*E12 -> 230.4 | H12: =G12+F12 -> 403.2
A14: Planning
A16: Foam | F16: 48 | G16: 96
A17: SAP | B17: Descrbtion ENG | C17: Descrbtion AR | D17: L2 cons | E17: L3 cons | F17: Units L2 | G17: Units L3 | H17: Total
A18: ASF-CIT-C43-FO01 | B18: Foam front back RH Citroen C43 | C18: فوم ظهرأمامي يمين سيتروين C43 | D18: 1 | E18: 1 | F18: =$F$16*D18 -> 48 | G18: =$G$16*E18 -> 96 | H18: =F18+G18 -> 144
A19: ASF-CIT-C43-FO02 | B19: Foam front back LH Citroen C43 | C19: فوم ظهرأمامي شمال سيتروين C43 | D19: 1 | E19: 1 | F19: =$F$16*D19 -> 48 | G19: =$G$16*E19 -> 96 | H19: =F19+G19 -> 144
A20: ASF-CIT-C43-FO03 | B20: Foam front cushion RH Citroen C43 | C20: فوم قاعدة أمامي يمين سيتروين C43 | D20: 1 | E20: 1 | F20: =$F$16*D20 -> 48 | G20: =$G$16*E20 -> 96 | H20: =F20+G20 -> 144
A21: ASF-CIT-C43-FO04 | B21: Foam front cushion LH Citroen C43 | C21: فوم قاعدة أمامي شمال سيتروين C43 | D21: 1 | E21: 1 | F21: =$F$16*D21 -> 48 | G21: =$G$16*E21 -> 96 | H21: =F21+G21 -> 144
A22: ASF-CIT-C43-FO05 | B22: Foam back 40% Citroen C43 | C22: فوم ظهر 40% سيتروين C43 | D22: 1 | E22: 1 | F22: =$F$16*D22 -> 48 | G22: =$G$16*E22 -> 96 | H22: =F22+G22 -> 144
A23: ASF-CIT-C43L3-FO06 | B23: Foam back 60% Citroen C43 Lvl 3 | C23: فوم ظهر 60% سيتروين C43 Lvl 3 | D23: 0 | E23: 1 | F23: =$F$16*D23 -> 0 | G23: =$G$16*E23 -> 96 | H23: =F23+G23 -> 96
A24: ASF-CIT-C43L2-FO06 | B24: Citroen Foam C43 Lvl 2 back 60% | C24: فوم سيتروينC43 Lvl 2 ظهر 60% | D24: 1 | E24: 0 | F24: =$F$16*D24 -> 48 | G24: =$G$16*E24 -> 0 | H24: =F24+G24 -> 48
A25: ASF-CIT-C43-FO07 | B25: Foam cushion 100% Citroen C43 | C25: فوم قاعدة خلفي 100% سيتروين C43 | D25: 1 | E25: 1 | F25: =$F$16*D25 -> 48 | G25: =$G$16*E25 -> 96 | H25: =F25+G25 -> 144
A28: SAP | B28: Descrbtion ENG | C28: Descrbtion AR | D28: L2 cons | E28: L3 cons | F28: Units L2 | G28: Units L3 | H28: Total
A29: ASF-CIT-C43L3-CH01 | B29: Chassis Insert Cushion100% Citroen C43L3 | C29: شاسيه 100% قاعدة سيتروين Lvl 3 | D29: 0 | E29: 1 | F29: =$F$16*D29 -> 0 | G29: =$G$16*E29 -> 96 | H29: =G29+F29 -> 96
A30: ASF-CIT-C43L2-CH01 | B30: Chassis Insert Cushion100% Citroen C43L2 | C30: شاسيه 100% قاعدة سيتروين Lvl 2 | D30: 1 | E30: 0 | F30: =$F$16*D30 -> 48 | G30: =$G$16*E30 -> 0 | H30: =G30+F30 -> 48
A32: Trim covers | F32: 48 | G32: 96
A33: SAP | B33: Descrbtion ENG | C33: Descrbtion AR | D33: L2 cons | E33: L3 cons | F33: Units L2 | G33: Units L3 | H33: Total
A34: ASF-C43-L3-TC3-01 | B34: Trim cover Front cushion RH C43 Lvl 3 | C34: كسوة قاعدة أمامي يمين Lvl 3 C43 | D34: 0 | E34: 1 | F34: =$F$32*D34 -> 0 | G34: =$G$32*E34 -> 96 | H34: =G34+F34 -> 96
A35: ASF-C43-L3-TC4-01 | B35: Trim cover Front cushion LH C43 Lvl 3 | C35: كسوة قاعدة أمامي شمال Lvl 3 C43 | D35: 0 | E35: 1 | F35: =$F$32*D35 -> 0 | G35: =$G$32*E35 -> 96 | H35: =G35+F35 -> 96
A36: ASF-C43-L3-TC5-01 | B36: Trim cover back 40% C43 Lvl 3 white | C36: كسوة ظهر 40% Lvl 3 C43 | D36: 0 | E36: 1 | F36: =$F$32*D36 -> 0 | G36: =$G$32*E36 -> 96 | H36: =G36+F36 -> 96
A37: ASF-C43-L3-TC6-01 | B37: Trim cover back 60% C43 Lvl 3 white | C37: كسوة ظهر 60% Lvl 3 C43 | D37: 0 | E37: 1 | F37: =$F$32*D37 -> 0 | G37: =$G$32*E37 -> 96 | H37: =G37+F37 -> 96
A38: ASF-C43-L3-TC7-01 | B38: Trim cover cushion 100% C43 Lvl 3 white | C38: كسوة قاعدة 100% Lvl 3 C43 | D38: 0 | E38: 1 | F38: =$F$32*D38 -> 0 | G38: =$G$32*E38 -> 96 | H38: =G38+F38 -> 96
A39: ASF-C43-L2-TC4-90 | B39: Trim cover Front cushion RH C43 Lvl2 | C39: كسوة قاعدة أمامي يمين Lvl 2 C43 اسود | D39: 1 | E39: 0 | F39: =$F$32*D39 -> 48 | G39: =$G$32*E39 -> 0 | H39: =G39+F39 -> 48
A40: ASF-C43-L2-TC5-90 | B40: Trim cover Front cushion LH C43 Lvl2 | C40: كسوة قاعدة أمامي شمال Lvl 2 C43 اسود | D40: 1 | E40: 0 | F40: =$F$32*D40 -> 48 | G40: =$G$32*E40 -> 0 | H40: =G40+F40 -> 48
A41: ASF-C43-L2-TC6-90 | B41: Trim cover back 40% C43 Lvl 2 Black | C41: كسوة ظهر 40% Lvl 2 C43 اسود | D41: 1 | E41: 0 | F41: =$F$32*D41 -> 48 | G41: =$G$32*E41 -> 0 | H41: =G41+F41 -> 48
A42: ASF-C43-L2-TC7-90 | B42: Trim cover back 60% C43 Lvl 2 Black | C42: كسوة ظهر 60% Lvl 2 C43 اسود | D42: 1 | E42: 0 | F42: =$F$32*D42 -> 48 | G42: =$G$32*E42 -> 0 | H42: =G42+F42 -> 48
A43: ASF-C43-L2-TC8-90 | B43: Trim cover cushion 100% C43 Lvl 2 Black | C43: كسوة قاعدة 100% Lvl 2 C43 اسود | D43: 1 | E43: 0 | F43: =$F$32*D43 -> 48 | G43: =$G$32*E43 -> 0 | H43: =G43+F43 -> 48

Sheet Required orders
A1: Lots required from Stellantis
A2: Month | B2: L2 | C2: L3
A3: June | B3: 1 | C3: 3
A4: July | B4: 6 | C4: 7
A5: Aug | B5: 4 | C5: 6 | F5: =4*48 -> 192
A6: Sep | B6: 4 | C6: 8 | F6: =6*48 -> 288
A7: Oct | B7: 6 | C7: 9
A8: Nov | B8: 5 | C8: 7
A9: Dec | B9: 5 | C9: 7
A10: Sum | B10: =SUM(B3:B9) -> 31 | C10: =SUM(C3:C9) -> 47
